<?xml version="1.0" encoding="utf-8"?>
<mujoco model="aloha">
  <compiler angle="radian" coordinate="local" meshdir="meshes" autolimits="true"/>
  <option timestep="0.002" integrator="implicitfast"/>
  <default>
    <joint damping="0.1" armature="0.01"/>
    <geom contype="0" conaffinity="1" friction="1.0 0.005 0.0001"/>
  </default>
  <asset>
  </asset>
  <worldbody>
    <geom name="ground" type="plane" size="10 10 0.1" contype="1" conaffinity="1" rgba="0.85 0.85 0.85 1"/>
    <body name="base" pos="0 0 0.600">
      <freejoint name="root"/>
      <inertial pos="0.000000 0.000000 0.000000" mass="5.000000" diaginertia="4.000000e-2 4.000000e-2 8.000000e-2"/>
      <body name="L_shoulder" pos="0.000000 0.250000 0.080000">
        <joint name="L_WAIST" type="hinge" range="-3.1400 3.1400" limited="true" axis="0.000000 0.000000 1.000000" pos="0 0 0" ref="0.000000"/>
        <inertial pos="0.000000 0.000000 0.000000" mass="0.700000" diaginertia="8.000000e-4 8.000000e-4 8.000000e-4"/>
        <body name="L_upper_arm" pos="0.000000 0.000000 0.060000">
          <joint name="L_SHOULDER" type="hinge" range="-1.8500 1.8500" limited="true" axis="0.000000 1.000000 0.000000" pos="0 0 0" ref="0.000000"/>
          <inertial pos="0.000000 0.000000 0.000000" mass="0.500000" diaginertia="3.000000e-3 3.000000e-3 2.000000e-4"/>
          <body name="L_forearm" pos="0.000000 0.000000 0.300000">
            <joint name="L_ELBOW" type="hinge" range="-1.8500 1.8500" limited="true" axis="0.000000 1.000000 0.000000" pos="0 0 0" ref="0.000000"/>
            <inertial pos="0.000000 0.000000 0.000000" mass="0.350000" diaginertia="2.000000e-3 2.000000e-3 1.500000e-4"/>
            <body name="L_wrist_pitch" pos="0.300000 0.000000 0.000000">
              <joint name="L_FOREARM_roll" type="hinge" range="-3.1400 3.1400" limited="true" axis="1.000000 0.000000 0.000000" pos="0 0 0" ref="0.000000"/>
              <inertial pos="0.000000 0.000000 0.000000" mass="0.150000" diaginertia="1.000000e-4 1.000000e-4 1.000000e-4"/>
              <body name="L_wrist_roll" pos="0.080000 0.000000 0.000000">
                <joint name="L_WRIST_pitch" type="hinge" range="-1.7400 2.1400" limited="true" axis="0.000000 1.000000 0.000000" pos="0 0 0" ref="0.200000"/>
                <inertial pos="0.000000 0.000000 0.000000" mass="0.100000" diaginertia="5.000000e-5 5.000000e-5 5.000000e-5"/>
                <body name="L_gripper_base" pos="0.060000 0.000000 0.000000">
                  <joint name="L_WRIST_roll" type="hinge" range="-3.1400 3.1400" limited="true" axis="1.000000 0.000000 0.000000" pos="0 0 0" ref="0.000000"/>
                  <inertial pos="0.000000 0.000000 0.000000" mass="0.100000" diaginertia="5.000000e-5 5.000000e-5 5.000000e-5"/>
                  <body name="L_gripper_jaw" pos="0.045000 0.000000 0.000000">
                    <joint name="L_GRIPPER" type="slide" range="0.0000 0.0400" limited="true" axis="0.000000 1.000000 0.000000" pos="0 0 0" ref="0.020000"/>
                    <inertial pos="0.000000 0.000000 0.000000" mass="0.030000" diaginertia="1.000000e-5 1.000000e-5 1.000000e-5"/>
                  </body>
                </body>
              </body>
            </body>
          </body>
        </body>
      </body>
      <body name="R_shoulder" pos="0.000000 -0.250000 0.080000">
        <joint name="R_WAIST" type="hinge" range="-3.1400 3.1400" limited="true" axis="0.000000 0.000000 1.000000" pos="0 0 0" ref="0.000000"/>
        <inertial pos="0.000000 0.000000 0.000000" mass="0.700000" diaginertia="8.000000e-4 8.000000e-4 8.000000e-4"/>
        <body name="R_upper_arm" pos="0.000000 0.000000 0.060000">
          <joint name="R_SHOULDER" type="hinge" range="-1.8500 1.8500" limited="true" axis="0.000000 1.000000 0.000000" pos="0 0 0" ref="0.000000"/>
          <inertial pos="0.000000 0.000000 0.000000" mass="0.500000" diaginertia="3.000000e-3 3.000000e-3 2.000000e-4"/>
          <body name="R_forearm" pos="0.000000 0.000000 0.300000">
            <joint name="R_ELBOW" type="hinge" range="-1.8500 1.8500" limited="true" axis="0.000000 1.000000 0.000000" pos="0 0 0" ref="0.000000"/>
            <inertial pos="0.000000 0.000000 0.000000" mass="0.350000" diaginertia="2.000000e-3 2.000000e-3 1.500000e-4"/>
            <body name="R_wrist_pitch" pos="0.300000 0.000000 0.000000">
              <joint name="R_FOREARM_roll" type="hinge" range="-3.1400 3.1400" limited="true" axis="1.000000 0.000000 0.000000" pos="0 0 0" ref="0.000000"/>
              <inertial pos="0.000000 0.000000 0.000000" mass="0.150000" diaginertia="1.000000e-4 1.000000e-4 1.000000e-4"/>
              <body name="R_wrist_roll" pos="0.080000 0.000000 0.000000">
                <joint name="R_WRIST_pitch" type="hinge" range="-1.7400 2.1400" limited="true" axis="0.000000 1.000000 0.000000" pos="0 0 0" ref="0.200000"/>
                <inertial pos="0.000000 0.000000 0.000000" mass="0.100000" diaginertia="5.000000e-5 5.000000e-5 5.000000e-5"/>
                <body name="R_gripper_base" pos="0.060000 0.000000 0.000000">
                  <joint name="R_WRIST_roll" type="hinge" range="-3.1400 3.1400" limited="true" axis="1.000000 0.000000 0.000000" pos="0 0 0" ref="0.000000"/>
                  <inertial pos="0.000000 0.000000 0.000000" mass="0.100000" diaginertia="5.000000e-5 5.000000e-5 5.000000e-5"/>
                  <body name="R_gripper_jaw" pos="0.045000 0.000000 0.000000">
                    <joint name="R_GRIPPER" type="slide" range="0.0000 0.0400" limited="true" axis="0.000000 1.000000 0.000000" pos="0 0 0" ref="0.020000"/>
                    <inertial pos="0.000000 0.000000 0.000000" mass="0.030000" diaginertia="1.000000e-5 1.000000e-5 1.000000e-5"/>
                  </body>
                </body>
              </body>
            </body>
          </body>
        </body>
      </body>
    </body>
  </worldbody>
  <actuator>
    <motor name="L_WAIST" joint="L_WAIST" ctrlrange="-8.000 8.000" gear="1"/>
    <motor name="L_SHOULDER" joint="L_SHOULDER" ctrlrange="-8.000 8.000" gear="1"/>
    <motor name="L_ELBOW" joint="L_ELBOW" ctrlrange="-6.000 6.000" gear="1"/>
    <motor name="L_FOREARM_roll" joint="L_FOREARM_roll" ctrlrange="-3.000 3.000" gear="1"/>
    <motor name="L_WRIST_pitch" joint="L_WRIST_pitch" ctrlrange="-3.000 3.000" gear="1"/>
    <motor name="L_WRIST_roll" joint="L_WRIST_roll" ctrlrange="-2.000 2.000" gear="1"/>
    <motor name="L_GRIPPER" joint="L_GRIPPER" ctrlrange="-4.000 4.000" gear="1"/>
    <motor name="R_WAIST" joint="R_WAIST" ctrlrange="-8.000 8.000" gear="1"/>
    <motor name="R_SHOULDER" joint="R_SHOULDER" ctrlrange="-8.000 8.000" gear="1"/>
    <motor name="R_ELBOW" joint="R_ELBOW" ctrlrange="-6.000 6.000" gear="1"/>
    <motor name="R_FOREARM_roll" joint="R_FOREARM_roll" ctrlrange="-3.000 3.000" gear="1"/>
    <motor name="R_WRIST_pitch" joint="R_WRIST_pitch" ctrlrange="-3.000 3.000" gear="1"/>
    <motor name="R_WRIST_roll" joint="R_WRIST_roll" ctrlrange="-2.000 2.000" gear="1"/>
    <motor name="R_GRIPPER" joint="R_GRIPPER" ctrlrange="-4.000 4.000" gear="1"/>
  </actuator>
</mujoco>
